Workbook

Sheet راهنما
A1: راهنمای ممیزی پرونده‌های آلبومین — بیمارستان جم
A3: هدف
A4: تعیین خط پایه «درصد مصرف آلبومین مطابق اندیکاسیون»، کامل بودن مستندات، ویال‌های بدون سرنوشت و ریسک کسورات بیمه، پیش از اجرای فرم جدید درخواست آلبومین؛ و تکرار همین ممیزی ۳ ماه بعد برای سنجش اثر فرم.
A6: نمونه‌گیری
A7: ۱. از HIS فهرست همه بستری‌هایی را بگیرید که در دوره ممیزی آلبومین دریافت کرده‌اند (پیشنهاد: شهریور و مهر ۱۴۰۵).
A8: ۲. اولویت: بخش‌های 3A، 3B، 4A و 4B (بیشترین مصرف در بخش عمومی)، سپس ICU و I.C.U OH.
A9: ۳. از هر بخش ۳۰ پرونده به‌صورت تصادفی انتخاب کنید (اگر کمتر از ۳۰ بود، همه). با ۳۰ پرونده دقت برآورد حدود ±۱۸ درصد است و با ۱۲۰ پرونده در کل حدود ±۹ درصد.
A10: ۴. انتخاب تصادفی: فهرست را بر اساس شماره پرونده مرتب کنید و با RAND() یا هر nامین پرونده انتخاب کنید. پرونده‌ها را بر اساس «جالب بودن» انتخاب نکنید.
A12: نحوه تکمیل برگه «ممیزی»
A13: • فقط سلول‌های زرد را پر کنید. سلول‌های آبی فرمول‌اند و خودکار حساب می‌شوند.
A14: • کد اندیکاسیون را از روی آنچه در پرونده آمده تعیین کنید، نه از روی حدس. اگر از پرونده معلوم نیست: U0.
A15: • «معیار الزامی مستند است» فقط وقتی «بله» است که یافته یا آزمایش ستون D جدول اندیکاسیون‌ها پیش از تجویز در پرونده ثبت شده باشد.
... A33: راهنمای رنگ: زرد = ورود داده توسط ممیز | آبی = محاسبه خودکار

Sheet اندیکاسیون‌ها
A1: جدول مرجع اندیکاسیون‌ها (برگرفته از فرم درخواست آلبومین بیمارستان)
A2: کد | B2: طبقه | C2: اندیکاسیون | D2: معیار الزامی که باید در پرونده مستند باشد | E2: دوز طبق فرم | F2: سقف ویال ۲۰٪ کل دوره (برای ممیزی) | G2: نقطه پایان
A3: A1 | B3: الف | C3: پاراسنتز حجیم در سیروز | D3: خروج ≥ ۵ لیتر آسیت (یا هر حجم با کراتینین > ۱٫۵) | E3: ۶ تا ۸ گرم به ازای هر لیتر | F3: 8 | G3: پس از اتمام پاراسنتز
A4: A2 | B4: الف | C4: پریتونیت باکتریایی خودبه‌خودی (SBP) | D4: PMN مایع آسیت ≥ ۲۵۰ و یکی از: کراتینین > ۱، BUN > ۳۰، بیلی‌روبین > ۴ | E4: روز ۱: ۱٫۵ g/kg، روز ۳: ۱ g/kg (حداکثر ۱۰۰ گرم در روز) | F4: 20 | G4: فقط روز ۱ و ۳
A5: A3 | B5: الف | C5: سندرم هپاتورنال (HRS-AKI) | D5: سیروز + کراتینین > ۱٫۵، بدون شوک، عفونت فعال یا داروی نفروتوکسیک | E5: روز ۱ و ۲: ۱ g/kg، سپس ۲۰ تا ۴۰ گرم روزانه با تنگ‌کننده عروقی | F5: 68 | G5: بهبود کراتینین یا حداکثر ۱۴ روز
A6: A4 | B6: الف | C6: پلاسمافرز | D6: دستور پزشک متخصص و پروتکل آفرزیس | E6: آلبومین ۵٪ برای جایگزینی ۷۰ تا ۸۰٪ حجم پلاسمای خارج‌شده | G6: پایان هر جلسه
A7: B1 | B7: ب | C7: احیای حجم پس از جراحی قلب | D7: ≥ ۳ لیتر کریستالوئید بولوس در ۲۴ ساعت بدون پاسخ همودینامیک (مایع حین عمل حساب نمی‌شود) | E7: آلبومین ۵٪ یا معادل آن | F7: 2 | G7: پاسخ همودینامیک یا ۲۴ ساعت
A8: B2 | B8: ب | C8: رزکسیون بیش از ۴۰٪ کبد | D8: آلبومین سرم < ۲٫۵ و حجم داخل عروقی ناکافی با کریستالوئید | E8: ۲۰ تا ۲۵ گرم روزانه | F8: 12 | G8: آلبومین ≥ ۲٫۵ یا حداکثر ۴ روز
A9: B3 | B9: ب | C9: شوک سپتیک مقاوم | D9: نیاز به وازوپرسور پس از ≥ ۳۰ mL/kg کریستالوئید؛ امضای متخصص ICU | E9: حداکثر ۲۰ گرم در روز | F9: 4 | G9: حداکثر ۲ روز
A10: C1 | B10: ج | C10: سندرم نفروتیک شدید با آناسارکا یا ادم ریه | D10: پروتئینوری > ۳ g/day و مقاومت به فوروزماید (≥ ۱۶۰ mg بولوس + ≥ ۲۰ mg/h به مدت ۸ ساعت) | E10: ۲۰ تا ۲۵ گرم همراه با دیورتیک | F10: 3 | G10: دیورز کافی؛ تکرار با تأیید نفرولوژی
A11: C2 | B11: ج | C11: آسیت یا ادم مقاوم به دیورتیک در سیروز | D11: حداکثر دوز دیورتیک (اسپیرونولاکتون ۴۰۰ + فوروزماید ۱۶۰) + آلبومین < ۲ g/dL | E11: ۲۰ گرم | F11: 2 | G11: فقط روز ۱
A12: N1 | B12: بدون اندیکاسیون | C12: ترومای مغزی (TBI) | D12: منع مصرف | F12: 0
A13: N2 | B13: بدون اندیکاسیون | C13: اصلاح آلبومین پایین بدون علامت | F13: 0
A14: N3 | B14: بدون اندیکاسیون | C14: احیای حجم روتین در ICU | F14: 0
A15: N4 | B15: بدون اندیکاسیون | C15: سپسیس بدون شوک | F15: 0
A16: N5 | B16: بدون اندیکاسیون | C16: سوءتغذیه، سوءجذب، انتروپاتی دفع پروتئین | F16: 0
A17: N6 | B17: بدون اندیکاسیون | C17: افت فشار حین دیالیز / بهبود اولترافیلتراسیون | F17: 0
A18: N7 | B18: بدون اندیکاسیون | C18: ترومای عمده، شوک هموراژیک، ARDS | F18: 0
A19: N8 | B19: بدون اندیکاسیون | C19: انسفالوپاتی کبدی، پانکراتیت، نارسایی قلبی، آنمی | F19: 0
A20: N9 | B20: بدون اندیکاسیون | C20: هیپوآلبومینمی پیش از جراحی | F20: 0
A21: X1 | B21: خارج از جدول | C21: سایر موارد خارج از جدول | D21: مشاوره فارماکوتراپی و تأیید رئیس کمیته دارو و درمان یا معاون درمان
A22: U0 | B22: نامشخص | C22: اندیکاسیون از پرونده قابل تشخیص نیست | F22: 0
A24: سقف کل دوره از ستون‌های دوز و نقطه پایان همین فرم مشتق شده و فقط برای ممیزی است. اگر فرم در کمیته اصلاح شد، این جدول هم به‌روز شود.

Sheet ممیزی
A1: ثبت ممیزی پرونده‌های آلبومین — هر ردیف یک بستری
A2: ردیف | B2: شماره پرونده | C2: بخش | D2: بیمه پایه | E2: تاریخ پذیرش | F2: وزن (kg) | G2: کد اندیکاسیون (از پرونده) | H2: اندیکاسیون | I2: طبقه | J2: فرم درخواست کامل و امضاشده | K2: اندیکاسیون در دستور پزشک | L2: معیار الزامی در پرونده مستند است | M2: آزمایش‌های الزامی فرم ثبت شده | N2: دوز به گرم و نقطه پایان ذکر شده | O2: تأیید داروساز | P2: تأیید موارد خارج از معیار | Q2: ثبت تزریق همه ویال‌ها در گزارش پرستاری | R2: ویال تحویلی (HIS) | S2: ویال تزریق‌شده (پرستاری) | T2: ویال برگشتی | U2: سقف مرجع جدول | V2: سقف برای این بیمار (اختیاری) | W2: قیمت خرید هر ویال (ریال) | X2: ویال مازاد بر سقف | Y2: ویال بدون سرنوشت (تحویلی − تزریق − برگشت) | Z2: وضعیت اندیکاسیون | AA2: امتیاز مستندات | AB2: ارزش مصرف نامطابق (ریال) | AC2: سهم بیمه ثبت‌شده (ریال) | AD2: سهم بیمار ثبت‌شده (ریال) | AE2: پیام بیمه | AF2: یادداشت ممیز / اقدام
A3: =IF(B3="","",ROW()-2) | H3: =IF(G3="","",IFERROR(INDEX('اندیکاسیون‌ها'!$C$3:$C$22,MATCH(G3,'اندیکاسیون‌ها'!$A$3:$A$22,0)),"کد نامعتبر")) | I3: =IF(G3="","",IFERROR(INDEX('اندیکاسیون‌ها'!$B$3:$B$22,MATCH(G3,'اندیکاسیون‌ها'!$A$3:$A$22,0)),"")) | U3: =IF(G3="","",IFERROR(INDEX('اندیکاسیون‌ها'!$F$3:$F$22,MATCH(G3,'اندیکاسیون‌ها'!$A$3:$A$22,0)),"")) | X3: =IF(OR(B3="",IF(V3<>"",V3,U3)=""),"",MAX(0,N(R3)-N(T3)-IF(V3<>"",V3,U3))) | Y3: =IF(B3="","",N(R3)-N(S3)-N(T3)) | Z3: =IF(B3="","",IF(OR(G3="",G3="U0"),"اندیکاسیون نامشخص",IF(I3="بدون اندیکاسیون","بدون اندیکاسیون",IF(AND(I3="خارج از جدول",P3<>"بله"),"خارج از جدول بدون تأیید",IF(L3<>"بله","معیار مستند نشده",IF(N(X3)>0,"مطابق، دوز مازاد","مطابق")))))) | AA3: =IF(B3="","",IFERROR(COUNTIF(J3:Q3,"بله")/(COUNTIF(J3:Q3,"بله")+COUNTIF(J3:Q3,"خیر")),"")) | AB3: =IF(B3="","",IF(Z3="مطابق",0,IF(Z3="مطابق، دوز مازاد",N(X3)*N(W3),(N(R3)-N(T3))*N(W3)))) | AE3: =IF(B3="","",IF(AND(N(AC3)>0,NOT(OR(Z3="مطابق",Z3="مطابق، دوز مازاد"))),"ریسک کسورات",IF(AND(OR(Z3="مطابق",Z3="مطابق، دوز مازاد"),N(AC3)=0,D3<>"آزاد",D3<>""),"بررسی امکان دریافت از بیمه","")))
A4: =IF(B4="","",ROW()-2) | H4: =IF(G4="","",IFERROR(INDEX('اندیکاسیون‌ها'!$C$3:$C$22,MATCH(G4,'اندیکاسیون‌ها'!$A$3:$A$22,0)),"کد نامعتبر")) | I4: =IF(G4="","",IFERROR(INDEX('اندیکاسیون‌ها'!$B$3:$B$22,MATCH(G4,'اندیکاسیون‌ها'!$A$3:$A$22,0)),"")) | U4: =IF(G4="","",IFERROR(INDEX('اندیکاسیون‌ها'!$F$3:$F$22,MATCH(G4,'اندیکاسیون‌ها'!$A$3:$A$22,0)),"")) | X4: =IF(OR(B4="",IF(V4<>"",V4,U4)=""),"",MAX(0,N(R4)-N(T4)-IF(V4<>"",V4,U4))) | Y4: =IF(B4="","",N(R4)-N(S4)-N(T4)) | Z4: =IF(B4="","",IF(OR(G4="",G4="U0"),"اندیکاسیون نامشخص",IF(I4="بدون اندیکاسیون","بدون اندیکاسیون",IF(AND(I4="خارج از جدول",P4<>"بله"),"خارج از جدول بدون تأیید",IF(L4<>"بله","معیار مستند نشده",IF(N(X4)>0,"مطابق، دوز مازاد","مطابق")))))) | AA4: =IF(B4="","",IFERROR(COUNTIF(J4:Q4,"بله")/(COUNTIF(J4:Q4,"بله")+COUNTIF(J4:Q4,"خیر")),"")) | AB4: =IF(B4="","",IF(Z4="مطابق",0,IF(Z4="مطابق، دوز مازاد",N(X4)*N(W4),(N(R4)-N(T4))*N(W4)))) | AE4: =IF(B4="","",IF(AND(N(AC4)>0,NOT(OR(Z4="مطابق",Z4="مطابق، دوز مازاد"))),"ریسک کسورات",IF(AND(OR(Z4="مطابق",Z4="مطابق، دوز مازاد"),N(AC4)=0,D4<>"آزاد",D4<>""),"بررسی امکان دریافت از بیمه","")))
A5: =IF(B5="","",ROW()-2) | H5: =IF(G5="","",IFERROR(INDEX('اندیکاسیون‌ها'!$C$3:$C$22,MATCH(G5,'اندیکاسیون‌ها'!$A$3:$A$22,0)),"کد نامعتبر")) | I5: =IF(G5="","",IFERROR(INDEX('اندیکاسیون‌ها'!$B$3:$B$22,MATCH(G5,'اندیکاسیون‌ها'!$A$3:$A$22,0)),"")) | U5: =IF(G5="","",IFERROR(INDEX('اندیکاسیون‌ها'!$F$3:$F$22,MATCH(G5,'اندیکاسیون‌ها'!$A$3:$A$22,0)),"")) | X5: =IF(OR(B5="",IF(V5<>"",V5,U5)=""),"",MAX(0,N(R5)-N(T5)-IF(V5<>"",V5,U5))) | Y5: =IF(B5="","",N(R5)-N(S5)-N(T5)) | Z5: =IF(B5="","",IF(OR(G5="",G5="U0"),"اندیکاسیون نامشخص",IF(I5="بدون اندیکاسیون","بدون اندیکاسیون",IF(AND(I5="خارج از جدول",P5<>"بله"),"خارج از جدول بدون تأیید",IF(L5<>"بله","معیار مستند نشده",IF(N(X5)>0,"مطابق، دوز مازاد","مطابق")))))) | AA5: =IF(B5="","",IFERROR(COUNTIF(J5:Q5,"بله")/(COUNTIF(J5:Q5,"بله")+COUNTIF(J5:Q5,"خیر")),"")) | AB5: =IF(B5="","",IF(Z5="مطابق",0,IF(Z5="مطابق، دوز مازاد",N(X5)*N(W5),(N(R5)-N(T5))*N(W5)))) | AE5: =IF(B5="","",IF(AND(N(AC5)>0,NOT(OR(Z5="مطابق",Z5="مطابق، دوز مازاد"))),"ریسک کسورات",IF(AND(OR(Z5="مطابق",Z5="مطابق، دوز مازاد"),N(AC5)=0,D5<>"آزاد",D5<>""),"بررسی امکان دریافت از بیمه","")))
A6: =IF(B6="","",ROW()-2) | H6: =IF(G6="","",IFERROR(INDEX('اندیکاسیون‌ها'!$C$3:$C$22,MATCH(G6,'اندیکاسیون‌ها'!$A$3:$A$22,0)),"کد نامعتبر")) | I6: =IF(G6="","",IFERROR(INDEX('اندیکاسیون‌ها'!$B$3:$B$22,MATCH(G6,'اندیکاسیون‌ها'!$A$3:$A$22,0)),"")) | U6: =IF(G6="","",IFERROR(INDEX('اندیکاسیون‌ها'!$F$3:$F$22,MATCH(G6,'اندیکاسیون‌ها'!$A$3:$A$22,0)),"")) | X6: =IF(OR(B6="",IF(V6<>"",V6,U6)=""),"",MAX(0,N(R6)-N(T6)-IF(V6<>"",V6,U6))) | Y6: =IF(B6="","",N(R6)-N(S6)-N(T6)) | Z6: =IF(B6="","",IF(OR(G6="",G6="U0"),"اندیکاسیون نامشخص",IF(I6="بدون اندیکاسیون","بدون اندیکاسیون",IF(AND(I6="خارج از جدول",P6<>"بله"),"خارج از جدول بدون تأیید",IF(L6<>"بله","معیار مستند نشده",IF(N(X6)>0,"مطابق، دوز مازاد","مطابق")))))) | AA6: =IF(B6="","",IFERROR(COUNTIF(J6:Q6,"بله")/(COUNTIF(J6:Q6,"بله")+COUNTIF(J6:Q6,"خیر")),"")) | AB6: =IF(B6="","",IF(Z6="مطابق",0,IF(Z6="مطابق، دوز مازاد",N(X6)*N(W6),(N(R6)-N(T6))*N(W6)))) | AE6: =IF(B6="","",IF(AND(N(AC6)>0,NOT(OR(Z6="مطابق",Z6="مطابق، دوز مازاد"))),"ریسک کسورات",IF(AND(OR(Z6="مطابق",Z6="مطابق، دوز مازاد"),N(AC6)=0,D6<>"آزاد",D6<>""),"بررسی امکان دریافت از بیمه","")))
A7: =IF(B7="","",ROW()-2) | H7: =IF(G7="","",IFERROR(INDEX('اندیکاسیون‌ها'!$C$3:$C$22,MATCH(G7,'اندیکاسیون‌ها'!$A$3:$A$22,0)),"کد نامعتبر")) | I7: =IF(G7="","",IFERROR(INDEX('اندیکاسیون‌ها'!$B$3:$B$22,MATCH(G7,'اندیکاسیون‌ها'!$A$3:$A$22,0)),"")) | U7: =IF(G7="","",IFERROR(INDEX('اندیکاسیون‌ها'!$F$3:$F$22,MATCH(G7,'اندیکاسیون‌ها'!$A$3:$A$22,0)),"")) | X7: =IF(OR(B7="",IF(V7<>"",V7,U7)=""),"",MAX(0,N(R7)-N(T7)-IF(V7<>"",V7,U7))) | Y7: =IF(B7="","",N(R7)-N(S7)-N(T7)) | Z7: =IF(B7="","",IF(OR(G7="",G7="U0"),"اندیکاسیون نامشخص",IF(I7="بدون اندیکاسیون","بدون اندیکاسیون",IF(AND(I7="خارج از جدول",P7<>"بله"),"خارج از جدول بدون تأیید",IF(L7<>"بله","معیار مستند نشده",IF(N(X7)>0,"مطابق، دوز مازاد","مطابق")))))) | AA7: =IF(B7="","",IFERROR(COUNTIF(J7:Q7,"بله")/(COUNTIF(J7:Q7,"بله")+COUNTIF(J7:Q7,"خیر")),"")) | AB7: =IF(B7="","",IF(Z7="مطابق",0,IF(Z7="مطابق، دوز مازاد",N(X7)*N(W7),(N(R7)-N(T7))*N(W7)))) | AE7: =IF(B7="","",IF(AND(N(AC7)>0,NOT(OR(Z7="مطابق",Z7="مطابق، دوز مازاد"))),"ریسک کسورات",IF(AND(OR(Z7="مطابق",Z7="مطابق، دوز مازاد"),N(AC7)=0,D7<>"آزاد",D7<>""),"بررسی امکان دریافت از بیمه","")))
A8: =IF(B8="","",ROW()-2) | H8: =IF(G8="","",IFERROR(INDEX('اندیکاسیون‌ها'!$C$3:$C$22,MATCH(G8,'اندیکاسیون‌ها'!$A$3:$A$22,0)),"کد نامعتبر")) | I8: =IF(G8="","",IFERROR(INDEX('اندیکاسیون‌ها'!$B$3:$B$22,MATCH(G8,'اندیکاسیون‌ها'!$A$3:$A$22,0)),"")) | U8: =IF(G8="","",IFERROR(INDEX('اندیکاسیون‌ها'!$F$3:$F$22,MATCH(G8,'اندیکاسیون‌ها'!$A$3:$A$22,0)),"")) | X8: =IF(OR(B8="",IF(V8<>"",V8,U8)=""),"",MAX(0,N(R8)-N(T8)-IF(V8<>"",V8,U8))) | Y8: =IF(B8="","",N(R8)-N(S8)-N(T8)) | Z8: =IF(B8="","",IF(OR(G8="",G8="U0"),"اندیکاسیون نامشخص",IF(I8="بدون اندیکاسیون","بدون اندیکاسیون",IF(AND(I8="خارج از جدول",P8<>"بله"),"خارج از جدول بدون تأیید",IF(L8<>"بله","معیار مستند نشده",IF(N(X8)>0,"مطابق، دوز مازاد","مطابق")))))) | AA8: =IF(B8="","",IFERROR(COUNTIF(J8:Q8,"بله")/(COUNTIF(J8:Q8,"بله")+COUNTIF(J8:Q8,"خیر")),"")) | AB8: =IF(B8="","",IF(Z8="مطابق",0,IF(Z8="مطابق، دوز مازاد",N(X8)*N(W8),(N(R8)-N(T8))*N(W8)))) | AE8: =IF(B8="","",IF(AND(N(AC8)>0,NOT(OR(Z8="مطابق",Z8="مطابق، دوز مازاد"))),"ریسک کسورات",IF(AND(OR(Z8="مطابق",Z8="مطابق، دوز مازاد"),N(AC8)=0,D8<>"آزاد",D8<>""),"بررسی امکان دریافت از بیمه","")))
A9: =IF(B9="","",ROW()-2) | H9: =IF(G9="","",IFERROR(INDEX('اندیکاسیون‌ها'!$C$3:$C$22,MATCH(G9,'اندیکاسیون‌ها'!$A$3:$A$22,0)),"کد نامعتبر")) | I9: =IF(G9="","",IFERROR(INDEX('اندیکاسیون‌ها'!$B$3:$B$22,MATCH(G9,'اندیکاسیون‌ها'!$A$3:$A$22,0)),"")) | U9: =IF(G9="","",IFERROR(INDEX('اندیکاسیون‌ها'!$F$3:$F$22,MATCH(G9,'اندیکاسیون‌ها'!$A$3:$A$22,0)),"")) | X9: =IF(OR(B9="",IF(V9<>"",V9,U9)=""),"",MAX(0,N(R9)-N(T9)-IF(V9<>"",V9,U9))) | Y9: =IF(B9="","",N(R9)-N(S9)-N(T9)) | Z9: =IF(B9="","",IF(OR(G9="",G9="U0"),"اندیکاسیون نامشخص",IF(I9="بدون اندیکاسیون","بدون اندیکاسیون",IF(AND(I9="خارج از جدول",P9<>"بله"),"خارج از جدول بدون تأیید",IF(L9<>"بله","معیار مستند نشده",IF(N(X9)>0,"مطابق، دوز مازاد","مطابق")))))) | AA9: =IF(B9="","",IFERROR(COUNTIF(J9:Q9,"بله")/(COUNTIF(J9:Q9,"بله")+COUNTIF(J9:Q9,"خیر")),"")) | AB9: =IF(B9="","",IF(Z9="مطابق",0,IF(Z9="مطابق، دوز مازاد",N(X9)*N(W9),(N(R9)-N(T9))*N(W9)))) | AE9: =IF(B9="","",IF(AND(N(AC9)>0,NOT(OR(Z9="مطابق",Z9="مطابق، دوز مازاد"))),"ریسک کسورات",IF(AND(OR(Z9="مطابق",Z9="مطابق، دوز مازاد"),N(AC9)=0,D9<>"آزاد",D9<>""),"بررسی امکان دریافت از بیمه","")))
A10: =IF(B10="","",ROW()-2) | H10: =IF(G10="","",IFERROR(INDEX('اندیکاسیون‌ها'!$C$3:$C$22,MATCH(G10,'اندیکاسیون‌ها'!$A$3:$A$22,0)),"کد نامعتبر")) | I10: =IF(G10="","",IFERROR(INDEX('اندیکاسیون‌ها'!$B$3:$B$22,MATCH(G10,'اندیکاسیون‌ها'!$A$3:$A$22,0)),"")) | U10: =IF(G10="","",IFERROR(INDEX('اندیکاسیون‌ها'!$F$3:$F$22,MATCH(G10,'اندیکاسیون‌ها'!$A$3:$A$22,0)),"")) | X10: =IF(OR(B10="",IF(V10<>"",V10,U10)=""),"",MAX(0,N(R10)-N(T10)-IF(V10<>"",V10,U10))) | Y10: =IF(B10="","",N(R10)-N(S10)-N(T10)) | Z10: =IF(B10="","",IF(OR(G10="",G10="U0"),"اندیکاسیون نامشخص",IF(I10="بدون اندیکاسیون","بدون اندیکاسیون",IF(AND(I10="خارج از جدول",P10<>"بله"),"خارج از جدول بدون تأیید",IF(L10<>"بله","معیار مستند نشده",IF(N(X10)>0,"مطابق، دوز مازاد","مطابق")))))) | AA10: =IF(B10="","",IFERROR(COUNTIF(J10:Q10,"بله")/(COUNTIF(J10:Q10,"بله")+COUNTIF(J10:Q10,"خیر")),"")) | AB10: =IF(B10="","",IF(Z10="مطابق",0,IF(Z10="مطابق، دوز مازاد",N(X10)*N(W10),(N(R10)-N(T10))*N(W10)))) | AE10: =IF(B10="","",IF(AND(N(AC10)>0,NOT(OR(Z10="مطابق",Z10="مطابق، دوز مازاد"))),"ریسک کسورات",IF(AND(OR(Z10="مطابق",Z10="مطابق، دوز مازاد"),N(AC10)=0,D10<>"آزاد",D10<>""),"بررسی امکان دریافت از بیمه","")))
A11: =IF(B11="","",ROW()-2) | H11: =IF(G11="","",IFERROR(INDEX('اندیکاسیون‌ها'!$C$3:$C$22,MATCH(G11,'اندیکاسیون‌ها'!$A$3:$A$22,0)),"کد نامعتبر")) | I11: =IF(G11="","",IFERROR(INDEX('اندیکاسیون‌ها'!$B$3:$B$22,MATCH(G11,'اندیکاسیون‌ها'!$A$3:$A$22,0)),"")) | U11: =IF(G11="","",IFERROR(INDEX('اندیکاسیون‌ها'!$F$3:$F$22,MATCH(G11,'اندیکاسیون‌ها'!$A$3:$A$22,0)),"")) | X11: =IF(OR(B11="",IF(V11<>"",V11,U11)=""),"",MAX(0,N(R11)-N(T11)-IF(V11<>"",V11,U11))) | Y11: =IF(B11="","",N(R11)-N(S11)-N(T11)) | Z11: =IF(B11="","",IF(OR(G11="",G11="U0"),"اندیکاسیون نامشخص",IF(I11="بدون اندیکاسیون","بدون اندیکاسیون",IF(AND(I11="خارج از جدول",P11<>"بله"),"خارج از جدول بدون تأیید",IF(L11<>"بله","معیار مستند نشده",IF(N(X11)>0,"مطابق، دوز مازاد","مطابق")))))) | AA11: =IF(B11="","",IFERROR(COUNTIF(J11:Q11,"بله")/(COUNTIF(J11:Q11,"بله")+COUNTIF(J11:Q11,"خیر")),"")) | AB11: =IF(B11="","",IF(Z11="مطابق",0,IF(Z11="مطابق، دوز مازاد",N(X11)*N(W11),(N(R11)-N(T11))*N(W11)))) | AE11: =IF(B11="","",IF(AND(N(AC11)>0,NOT(OR(Z11="مطابق",Z11="مطابق، دوز مازاد"))),"ریسک کسورات",IF(AND(OR(Z11="مطابق",Z11="مطابق، دوز مازاد"),N(AC11)=0,D11<>"آزاد",D11<>""),"بررسی امکان دریافت از بیمه","")))
A12: =IF(B12="","",ROW()-2) | H12: =IF(G12="","",IFERROR(INDEX('اندیکاسیون‌ها'!$C$3:$C$22,MATCH(G12,'اندیکاسیون‌ها'!$A$3:$A$22,0)),"کد نامعتبر")) | I12: =IF(G12="","",IFERROR(INDEX('اندیکاسیون‌ها'!$B$3:$B$22,MATCH(G12,'اندیکاسیون‌ها'!$A$3:$A$22,0)),"")) | U12: =IF(G12="","",IFERROR(INDEX('اندیکاسیون‌ها'!$F$3:$F$22,MATCH(G12,'اندیکاسیون‌ها'!$A$3:$A$22,0)),"")) | X12: =IF(OR(B12="",IF(V12<>"",V12,U12)=""),"",MAX(0,N(R12)-N(T12)-IF(V12<>"",V12,U12))) | Y12: =IF(B12="","",N(R12)-N(S12)-N(T12)) | Z12: =IF(B12="","",IF(OR(G12="",G12="U0"),"اندیکاسیون نامشخص",IF(I12="بدون اندیکاسیون","بدون اندیکاسیون",IF(AND(I12="خارج از جدول",P12<>"بله"),"خارج از جدول بدون تأیید",IF(L12<>"بله","معیار مستند نشده",IF(N(X12)>0,"مطابق، دوز مازاد","مطابق")))))) | AA12: =IF(B12="","",IFERROR(COUNTIF(J12:Q12,"بله")/(COUNTIF(J12:Q12,"بله")+COUNTIF(J12:Q12,"خیر")),"")) | AB12: =IF(B12="","",IF(Z12="مطابق",0,IF(Z12="مطابق، دوز مازاد",N(X12)*N(W12),(N(R12)-N(T12))*N(W12)))) | AE12: =IF(B12="","",IF(AND(N(AC12)>0,NOT(OR(Z12="مطابق",Z12="مطابق، دوز مازاد"))),"ریسک کسورات",IF(AND(OR(Z12="مطابق",Z12="مطابق، دوز مازاد"),N(AC12)=0,D12<>"آزاد",D12<>""),"بررسی امکان دریافت از بیمه","")))
A13: =IF(B13="","",ROW()-2) | H13: =IF(G13="","",IFERROR(INDEX('اندیکاسیون‌ها'!$C$3:$C$22,MATCH(G13,'اندیکاسیون‌ها'!$A$3:$A$22,0)),"کد نامعتبر")) | I13: =IF(G13="","",IFERROR(INDEX('اندیکاسیون‌ها'!$B$3:$B$22,MATCH(G13,'اندیکاسیون‌ها'!$A$3:$A$22,0)),"")) | U13: =IF(G13="","",IFERROR(INDEX('اندیکاسیون‌ها'!$F$3:$F$22,MATCH(G13,'اندیکاسیون‌ها'!$A$3:$A$22,0)),"")) | X13: =IF(OR(B13="",IF(V13<>"",V13,U13)=""),"",MAX(0,N(R13)-N(T13)-IF(V13<>"",V13,U13))) | Y13: =IF(B13="","",N(R13)-N(S13)-N(T13)) | Z13: =IF(B13="","",IF(OR(G13="",G13="U0"),"اندیکاسیون نامشخص",IF(I13="بدون اندیکاسیون","بدون اندیکاسیون",IF(AND(I13="خارج از جدول",P13<>"بله"),"خارج از جدول بدون تأیید",IF(L13<>"بله","معیار مستند نشده",IF(N(X13)>0,"مطابق، دوز مازاد","مطابق")))))) | AA13: =IF(B13="","",IFERROR(COUNTIF(J13:Q13,"بله")/(COUNTIF(J13:Q13,"بله")+COUNTIF(J13:Q13,"خیر")),"")) | AB13: =IF(B13="","",IF(Z13="مطابق",0,IF(Z13="مطابق، دوز مازاد",N(X13)*N(W13),(N(R13)-N(T13))*N(W13)))) | AE13: =IF(B13="","",IF(AND(N(AC13)>0,NOT(OR(Z13="مطابق",Z13="مطابق، دوز مازاد"))),"ریسک کسورات",IF(AND(OR(Z13="مطابق",Z13="مطابق، دوز مازاد"),N(AC13)=0,D13<>"آزاد",D13<>""),"بررسی امکان دریافت از بیمه","")))
A14: =IF(B14="","",ROW()-2) | H14: =IF(G14="","",IFERROR(INDEX('اندیکاسیون‌ها'!$C$3:$C$22,MATCH(G14,'اندیکاسیون‌ها'!$A$3:$A$22,0)),"کد نامعتبر")) | I14: =IF(G14="","",IFERROR(INDEX('اندیکاسیون‌ها'!$B$3:$B$22,MATCH(G14,'اندیکاسیون‌ها'!$A$3:$A$22,0)),"")) | U14: =IF(G14="","",IFERROR(INDEX('اندیکاسیون‌ها'!$F$3:$F$22,MATCH(G14,'اندیکاسیون‌ها'!$A$3:$A$22,0)),"")) | X14: =IF(OR(B14="",IF(V14<>"",V14,U14)=""),"",MAX(0,N(R14)-N(T14)-IF(V14<>"",V14,U14))) | Y14: =IF(B14="","",N(R14)-N(S14)-N(T14)) | Z14: =IF(B14="","",IF(OR(G14="",G14="U0"),"اندیکاسیون نامشخص",IF(I14="بدون اندیکاسیون","بدون اندیکاسیون",IF(AND(I14="خارج از جدول",P14<>"بله"),"خارج از جدول بدون تأیید",IF(L14<>"بله","معیار مستند نشده",IF(N(X14)>0,"مطابق، دوز مازاد","مطابق")))))) | AA14: =IF(B14="","",IFERROR(COUNTIF(J14:Q14,"بله")/(COUNTIF(J14:Q14,"بله")+COUNTIF(J14:Q14,"خیر")),"")) | AB14: =IF(B14="","",IF(Z14="مطابق",0,IF(Z14="مطابق، دوز مازاد",N(X14)*N(W14),(N(R14)-N(T14))*N(W14)))) | AE14: =IF(B14="","",IF(AND(N(AC14)>0,NOT(OR(Z14="مطابق",Z14="مطابق، دوز مازاد"))),"ریسک کسورات",IF(AND(OR(Z14="مطابق",Z14="مطابق، دوز مازاد"),N(AC14)=0,D14<>"آزاد",D14<>""),"بررسی امکان دریافت از بیمه","")))
... A202: =IF(B202="","",ROW()-2) | H202: =IF(G202="","",IFERROR(INDEX('اندیکاسیون‌ها'!$C$3:$C$22,MATCH(G202,'اندیکاسیون‌ها'!$A$3:$A$22,0)),"کد نامعتبر")) | I202: =IF(G202="","",IFERROR(INDEX('اندیکاسیون‌ها'!$B$3:$B$22,MATCH(G202,'اندیکاسیون‌ها'!$A$3:$A$22,0)),"")) | U202: =IF(G202="","",IFERROR(INDEX('اندیکاسیون‌ها'!$F$3:$F$22,MATCH(G202,'اندیکاسیون‌ها'!$A$3:$A$22,0)),"")) | X202: =IF(OR(B202="",IF(V202<>"",V202,U202)=""),"",MAX(0,N(R202)-N(T202)-IF(V202<>"",V202,U202))) | Y202: =IF(B202="","",N(R202)-N(S202)-N(T202)) | Z202: =IF(B202="","",IF(OR(G202="",G202="U0"),"اندیکاسیون نامشخص",IF(I202="بدون اندیکاسیون","بدون اندیکاسیون",IF(AND(I202="خارج از جدول",P202<>"بله"),"خارج از جدول بدون تأیید",IF(L202<>"بله","معیار مستند نشده",IF(N(X202)>0,"مطابق، دوز مازاد","مطابق")))))) | AA202: =IF(B202="","",IFERROR(COUNTIF(J202:Q202,"بله")/(COUNTIF(J202:Q202,"بله")+COUNTIF(J202:Q202,"خیر")),"")) | AB202: =IF(B202="","",IF(Z202="مطابق",0,IF(Z202="مطابق، دوز مازاد",N(X202)*N(W202),(N(R202)-N(T202))*N(W202)))) | AE202: =IF(B202="","",IF(AND(N(AC202)>0,NOT(OR(Z202="مطابق",Z202="مطابق، دوز مازاد"))),"ریسک کسورات",IF(AND(OR(Z202="مطابق",Z202="مطابق، دوز مازاد"),N(AC202)=0,D202<>"آزاد",D202<>""),"بررسی امکان دریافت از بیمه","")))

Sheet فهرست‌ها
A1: ICU | B1: تامین اجتماعی | C1: بله
A2: I.C.U OH | B2: سلامت | C2: خیر
A3: C.C.U | B3: نیروهای مسلح | C3: نامرتبط
A4: بخش 2 | B4: سایر بیمه‌ها
A5: بخش 3A | B5: آزاد
A6: بخش 3B
A7: بخش 4A
A8: بخش 4B
A9: سایر

Sheet خلاصه
A1: خلاصه نتایج ممیزی آلبومین
A4: کلیات
A5: تعداد پرونده ممیزی‌شده | B5: =COUNTA(ممیزی!$B$3:$B$202) -> 0
A7: وضعیت اندیکاسیون (تعداد و درصد) | C7: درصد
A8: مطابق | B8: =COUNTIF(ممیزی!$Z$3:$Z$202,"مطابق") -> 0 | C8: =IFERROR(B8/B5,0) -> 0
A9: مطابق، دوز مازاد | B9: =COUNTIF(ممیزی!$Z$3:$Z$202,"مطابق، دوز مازاد") -> 0 | C9: =IFERROR(B9/B5,0) -> 0
A10: معیار مستند نشده | B10: =COUNTIF(ممیزی!$Z$3:$Z$202,"معیار مستند نشده") -> 0 | C10: =IFERROR(B10/B5,0) -> 0
A11: بدون اندیکاسیون | B11: =COUNTIF(ممیزی!$Z$3:$Z$202,"بدون اندیکاسیون") -> 0 | C11: =IFERROR(B11/B5,0) -> 0
A12: خارج از جدول بدون تأیید | B12: =COUNTIF(ممیزی!$Z$3:$Z$202,"خارج از جدول بدون تأیید") -> 0 | C12: =IFERROR(B12/B5,0) -> 0
A13: اندیکاسیون نامشخص | B13: =COUNTIF(ممیزی!$Z$3:$Z$202,"اندیکاسیون نامشخص") -> 0 | C13: =IFERROR(B13/B5,0) -> 0
A14: نرخ مصرف مطابق اندیکاسیون (شامل دوز مازاد) | B14: =IFERROR((B8+B9)/B5,0) -> 0
A16: ویال و ریال
A17: ویال تحویلی | B17: =SUM(ممیزی!$R$3:$R$202) -> 0
A18: ویال تزریق‌شده (ثبت پرستاری) | B18: =SUM(ممیزی!$S$3:$S$202) -> 0
A19: ویال برگشتی | B19: =SUM(ممیزی!$T$3:$T$202) -> 0
A20: ویال بدون سرنوشت | B20: =SUM(ممیزی!$Y$3:$Y$202) -> 0
A21: ویال مازاد بر سقف (فقط در موارد با اندیکاسیون مطابق) | B21: =SUMIF(ممیزی!$Z$3:$Z$202,"مطابق، دوز مازاد",ممیزی!$X$3:$X$202) -> 0
A22: ارزش مصرف نامطابق (ریال) | B22: =SUM(ممیزی!$AB$3:$AB$202) -> 0
A23: میانگین امتیاز مستندات | B23: =IFERROR(AVERAGE(ممیزی!$AA$3:$AA$202),0) -> 0
A25: کامل بودن مستندات (درصد «بله» از موارد مرتبط)
A26: فرم درخواست کامل و امضاشده | B26: =IFERROR(COUNTIF(ممیزی!$J$3:$J$202,"بله")/(COUNTIF(ممیزی!$J$3:$J$202,"بله")+COUNTIF(ممیزی!$J$3:$J$202,"خیر")),0) -> 0
A27: اندیکاسیون در دستور پزشک | B27: =IFERROR(COUNTIF(ممیزی!$K$3:$K$202,"بله")/(COUNTIF(ممیزی!$K$3:$K$202,"بله")+COUNTIF(ممیزی!$K$3:$K$202,"خیر")),0) -> 0
A28: معیار الزامی در پرونده مستند است | B28: =IFERROR(COUNTIF(ممیزی!$L$3:$L$202,"بله")/(COUNTIF(ممیزی!$L$3:$L$202,"بله")+COUNTIF(ممیزی!$L$3:$L$202,"خیر")),0) -> 0
A29: آزمایش‌های الزامی فرم ثبت شده | B29: =IFERROR(COUNTIF(ممیزی!$M$3:$M$202,"بله")/(COUNTIF(ممیزی!$M$3:$M$202,"بله")+COUNTIF(ممیزی!$M$3:$M$202,"خیر")),0) -> 0
A30: دوز به گرم و نقطه پایان ذکر شده | B30: =IFERROR(COUNTIF(ممیزی!$N$3:$N$202,"بله")/(COUNTIF(ممیزی!$N$3:$N$202,"بله")+COUNTIF(ممیزی!$N$3:$N$202,"خیر")),0) -> 0
A31: تأیید داروساز | B31: =IFERROR(COUNTIF(ممیزی!$O$3:$O$202,"بله")/(COUNTIF(ممیزی!$O$3:$O$202,"بله")+COUNTIF(ممیزی!$O$3:$O$202,"خیر")),0) -> 0
A32: تأیید موارد خارج از معیار | B32: =IFERROR(COUNTIF(ممیزی!$P$3:$P$202,"بله")/(COUNTIF(ممیزی!$P$3:$P$202,"بله")+COUNTIF(ممیزی!$P$3:$P$202,"خیر")),0) -> 0
A33: ثبت تزریق همه ویال‌ها در گزارش پرستاری | B33: =IFERROR(COUNTIF(ممیزی!$Q$3:$Q$202,"بله")/(COUNTIF(ممیزی!$Q$3:$Q$202,"بله")+COUNTIF(ممیزی!$Q$3:$Q$202,"خیر")),0) -> 0
A35: بیمه
A36: پرونده با «ریسک کسورات» | B36: =COUNTIF(ممیزی!$AE$3:$AE$202,"ریسک کسورات") -> 0
A37: پرونده مطابق که سهم بیمه ندارد (بررسی امکان دریافت) | B37: =COUNTIF(ممیزی!$AE$3:$AE$202,"بررسی امکان دریافت از بیمه") -> 0
A38: جمع سهم بیمه ثبت‌شده (ریال) | B38: =SUM(ممیزی!$AC$3:$AC$202) -> 0
A39: جمع سهم بیمار ثبت‌شده (ریال) | B39: =SUM(ممیزی!$AD$3:$AD$202) -> 0
A41: به تفکیک بخش
A42: بخش | B42: پرونده | C42: مطابق (با دوز مازاد) | D42: نرخ مطابق | E42: ارزش نامطابق (ریال) | F42: ویال بدون سرنوشت
A43: ICU | B43: =COUNTIF(ممیزی!$C$3:$C$202,"ICU") -> 0 | C43: =COUNTIFS(ممیزی!$C$3:$C$202,"ICU",ممیزی!$Z$3:$Z$202,"مطابق")+COUNTIFS(ممیزی!$C$3:$C$202,"ICU",ممیزی!$Z$3:$Z$202,"مطابق، دوز مازاد") -> 0 | D43: =IFERROR(C43/B43,0) -> 0 | E43: =SUMIF(ممیزی!$C$3:$C$202,"ICU",ممیزی!$AB$3:$AB$202) -> 0 | F43: =SUMIF(ممیزی!$C$3:$C$202,"ICU",ممیزی!$Y$3:$Y$202) -> 0
A44: I.C.U OH | B44: =COUNTIF(ممیزی!$C$3:$C$202,"I.C.U OH") -> 0 | C44: =COUNTIFS(ممیزی!$C$3:$C$202,"I.C.U OH",ممیزی!$Z$3:$Z$202,"مطابق")+COUNTIFS(ممیزی!$C$3:$C$202,"I.C.U OH",ممیزی!$Z$3:$Z$202,"مطابق، دوز مازاد") -> 0 | D44: =IFERROR(C44/B44,0) -> 0 | E44: =SUMIF(ممیزی!$C$3:$C$202,"I.C.U OH",ممیزی!$AB$3:$AB$202) -> 0 | F44: =SUMIF(ممیزی!$C$3:$C$202,"I.C.U OH",ممیزی!$Y$3:$Y$202) -> 0
A45: C.C.U | B45: =COUNTIF(ممیزی!$C$3:$C$202,"C.C.U") -> 0 | C45: =COUNTIFS(ممیزی!$C$3:$C$202,"C.C.U",ممیزی!$Z$3:$Z$202,"مطابق")+COUNTIFS(ممیزی!$C$3:$C$202,"C.C.U",ممیزی!$Z$3:$Z$202,"مطابق، دوز مازاد") -> 0 | D45: =IFERROR(C45/B45,0) -> 0 | E45: =SUMIF(ممیزی!$C$3:$C$202,"C.C.U",ممیزی!$AB$3:$AB$202) -> 0 | F45: =SUMIF(ممیزی!$C$3:$C$202,"C.C.U",ممیزی!$Y$3:$Y$202) -> 0
A46: بخش 2 | B46: =COUNTIF(ممیزی!$C$3:$C$202,"بخش 2") -> 0 | C46: =COUNTIFS(ممیزی!$C$3:$C$202,"بخش 2",ممیزی!$Z$3:$Z$202,"مطابق")+COUNTIFS(ممیزی!$C$3:$C$202,"بخش 2",ممیزی!$Z$3:$Z$202,"مطابق، دوز مازاد") -> 0 | D46: =IFERROR(C46/B46,0) -> 0 | E46: =SUMIF(ممیزی!$C$3:$C$202,"بخش 2",ممیزی!$AB$3:$AB$202) -> 0 | F46: =SUMIF(ممیزی!$C$3:$C$202,"بخش 2",ممیزی!$Y$3:$Y$202) -> 0
A47: بخش 3A | B47: =COUNTIF(ممیزی!$C$3:$C$202,"بخش 3A") -> 0 | C47: =COUNTIFS(ممیزی!$C$3:$C$202,"بخش 3A",ممیزی!$Z$3:$Z$202,"مطابق")+COUNTIFS(ممیزی!$C$3:$C$202,"بخش 3A",ممیزی!$Z$3:$Z$202,"مطابق، دوز مازاد") -> 0 | D47: =IFERROR(C47/B47,0) -> 0 | E47: =SUMIF(ممیزی!$C$3:$C$202,"بخش 3A",ممیزی!$AB$3:$AB$202) -> 0 | F47: =SUMIF(ممیزی!$C$3:$C$202,"بخش 3A",ممیزی!$Y$3:$Y$202) -> 0
...
